<?xml version="1.0"?>
<robot xmlns:xacro="http://www.ros.org/wiki/xacro" name="arm">

  <link name="base_link"/>

  <!-- Shoulder -->
  <link name="shoulder_link">
    <visual>
      <geometry><cylinder radius="0.04" length="0.1"/></geometry>
    </visual>
    <collision>
      <geometry><cylinder radius="0.04" length="0.1"/></geometry>
    </collision>
    <inertial>
      <mass value="1.0"/>
      <inertia ixx="0.001" ixy="0" ixz="0" iyy="0.001" iyz="0" izz="0.001"/>
    </inertial>
  </link>

  <joint name="shoulder_joint" type="revolute">
    <parent link="base_link"/>
    <child link="shoulder_link"/>
    <origin xyz="0 0 0.05"/>
    <axis xyz="0 0 1"/>
    <limit lower="${-pi}" upper="${pi}" velocity="1.0" effort="10.0"/>
  </joint>

  <!-- Upper Arm -->
  <link name="upper_arm_link">
    <visual>
      <origin xyz="0 0 0.1"/>
      <geometry><box size="0.04 0.04 0.2"/></geometry>
    </visual>
    <collision>
      <origin xyz="0 0 0.1"/>
      <geometry><box size="0.04 0.04 0.2"/></geometry>
    </collision>
    <inertial>
      <mass value="0.8"/>
      <origin xyz="0 0 0.1"/>
      <inertia ixx="0.003" ixy="0" ixz="0" iyy="0.003" iyz="0" izz="0.001"/>
    </inertial>
  </link>

  <joint name="elbow_joint" type="revolute">
    <parent link="shoulder_link"/>
    <child link="upper_arm_link"/>
    <origin xyz="0 0 0.05"/>
    <axis xyz="0 1 0"/>
    <limit lower="${-pi/2}" upper="${pi/2}" velocity="1.0" effort="10.0"/>
  </joint>

  <!-- Forearm -->
  <link name="forearm_link">
    <visual>
      <origin xyz="0 0 0.075"/>
      <geometry><box size="0.03 0.03 0.15"/></geometry>
    </visual>
    <collision>
      <origin xyz="0 0 0.075"/>
      <geometry><box size="0.03 0.03 0.15"/></geometry>
    </collision>
    <inertial>
      <mass value="0.5"/>
      <origin xyz="0 0 0.075"/>
      <inertia ixx="0.001" ixy="0" ixz="0" iyy="0.001" iyz="0" izz="0.0005"/>
    </inertial>
  </link>

  <joint name="wrist_joint" type="revolute">
    <parent link="upper_arm_link"/>
    <child link="forearm_link"/>
    <origin xyz="0 0 0.2"/>
    <axis xyz="0 1 0"/>
    <limit lower="${-pi/2}" upper="${pi/2}" velocity="1.0" effort="5.0"/>
  </joint>

  <!-- Gripper Base -->
  <link name="gripper_base_link">
    <visual>
      <geometry><box size="0.06 0.04 0.02"/></geometry>
    </visual>
    <collision>
      <geometry><box size="0.06 0.04 0.02"/></geometry>
    </collision>
    <inertial>
      <mass value="0.2"/>
      <inertia ixx="0.0001" ixy="0" ixz="0" iyy="0.0001" iyz="0" izz="0.0001"/>
    </inertial>
  </link>

  <joint name="gripper_base_joint" type="fixed">
    <parent link="forearm_link"/>
    <child link="gripper_base_link"/>
    <origin xyz="0 0 0.15"/>
  </joint>

  <!-- Left Finger -->
  <link name="left_finger_link">
    <visual>
      <origin xyz="0 0 0.03"/>
      <geometry><box size="0.01 0.01 0.06"/></geometry>
    </visual>
    <collision>
      <origin xyz="0 0 0.03"/>
      <geometry><box size="0.01 0.01 0.06"/></geometry>
    </collision>
    <inertial>
      <mass value="0.05"/>
      <origin xyz="0 0 0.03"/>
      <inertia ixx="0.00001" ixy="0" ixz="0" iyy="0.00001" iyz="0" izz="0.00001"/>
    </inertial>
  </link>

  <joint name="left_finger_joint" type="prismatic">
    <parent link="gripper_base_link"/>
    <child link="left_finger_link"/>
    <origin xyz="0 0.015 0.01"/>
    <axis xyz="0 1 0"/>
    <limit lower="0.0" upper="0.03" velocity="0.1" effort="5.0"/>
  </joint>

  <!-- Right Finger (mirrored) -->
  <link name="right_finger_link">
    <visual>
      <origin xyz="0 0 0.03"/>
      <geometry><box size="0.01 0.01 0.06"/></geometry>
    </visual>
    <collision>
      <origin xyz="0 0 0.03"/>
      <geometry><box size="0.01 0.01 0.06"/></geometry>
    </collision>
    <inertial>
      <mass value="0.05"/>
      <origin xyz="0 0 0.03"/>
      <inertia ixx="0.00001" ixy="0" ixz="0" iyy="0.00001" iyz="0" izz="0.00001"/>
    </inertial>
  </link>

  <joint name="right_finger_joint" type="prismatic">
    <parent link="gripper_base_link"/>
    <child link="right_finger_link"/>
    <origin xyz="0 -0.015 0.01"/>
    <axis xyz="0 -1 0"/>
    <limit lower="0.0" upper="0.03" velocity="0.1" effort="5.0"/>
  </joint>

  <link name="tool_tip"/>

  <joint name="tool_tip_joint" type="fixed">
    <parent link="gripper_base_link"/>
    <child link="tool_tip"/>
    <origin xyz="0 0 0.06"/>  
  </joint>

  <!-- ros2_control -->
  <ros2_control name="ArmSystem" type="system">
    <hardware>
      <plugin>mock_components/GenericSystem</plugin>
    </hardware>
    <joint name="shoulder_joint">
      <command_interface name="position"/>
      <state_interface name="position"/>
      <state_interface name="velocity"/>
    </joint>
    <joint name="elbow_joint">
      <command_interface name="position"/>
      <state_interface name="position"/>
      <state_interface name="velocity"/>
    </joint>
    <joint name="wrist_joint">
      <command_interface name="position"/>
      <state_interface name="position"/>
      <state_interface name="velocity"/>
    </joint>
    <joint name="left_finger_joint">
      <command_interface name="position"/>
      <state_interface name="position"/>
      <state_interface name="velocity"/>
    </joint>
    <joint name="right_finger_joint">
      <command_interface name="position"/>
      <state_interface name="position"/>
      <state_interface name="velocity"/>
    </joint>
  </ros2_control>

</robot>